<?xml version="1.0" ?>
<robot name="ruxonros2" xmlns:xacro="http://www.ros.org/wiki/xacro">

<xacro:include filename="$(find ruxonros2_description)/urdf/materials.xacro" />
<xacro:include filename="$(find ruxonros2_description)/urdf/ruxonros2.trans" />
<xacro:include filename="$(find ruxonros2_description)/urdf/ruxonros2.gazebo" />
<link name="base_link">
  <inertial>
    <origin xyz="-4.2122347559657015e-06 0.05286317902394757 0.06821395731828753" rpy="0 0 0"/>
    <mass value="7.210677442504244"/>
    <inertia ixx="0.052311" iyy="0.027906" izz="0.060508" ixy="2e-06" iyz="0.000903" ixz="-0.0"/>
  </inertial>
  <visual>
    <origin xyz="0 0 0" rpy="0 0 0"/>
    <geometry>
      <mesh filename="package://ruxonros2_description/meshes/base_link.stl" scale="0.001 0.001 0.001"/>
    </geometry>
    <material name="silver"/>
  </visual>
  <collision>
    <origin xyz="0 0 0" rpy="0 0 0"/>
    <geometry>
      <mesh filename="package://ruxonros2_description/meshes/base_link.stl" scale="0.001 0.001 0.001"/>
    </geometry>
  </collision>
</link>

<link name="X_1">
  <inertial>
    <origin xyz="-0.0009062160060217307 -0.0036400126746291457 0.07072609812342064" rpy="0 0 0"/>
    <mass value="10.666992672889636"/>
    <inertia ixx="0.057671" iyy="0.068578" izz="0.055192" ixy="-0.000208" iyz="0.002535" ixz="0.003277"/>
  </inertial>
  <visual>
    <origin xyz="-0.0 -0.023029 -0.111" rpy="0 0 0"/>
    <geometry>
      <mesh filename="package://ruxonros2_description/meshes/X_1.stl" scale="0.001 0.001 0.001"/>
    </geometry>
    <material name="silver"/>
  </visual>
  <collision>
    <origin xyz="-0.0 -0.023029 -0.111" rpy="0 0 0"/>
    <geometry>
      <mesh filename="package://ruxonros2_description/meshes/X_1.stl" scale="0.001 0.001 0.001"/>
    </geometry>
  </collision>
</link>

<link name="Y_1">
  <inertial>
    <origin xyz="-0.05722519236271014 0.010962120725895398 0.10397673856857204" rpy="0 0 0"/>
    <mass value="10.813925675934529"/>
    <inertia ixx="0.116326" iyy="0.13156" izz="0.042847" ixy="6.7e-05" iyz="-0.004427" ixz="-0.001298"/>
  </inertial>
  <visual>
    <origin xyz="-0.05713 -0.002855 -0.28806" rpy="0 0 0"/>
    <geometry>
      <mesh filename="package://ruxonros2_description/meshes/Y_1.stl" scale="0.001 0.001 0.001"/>
    </geometry>
    <material name="silver"/>
  </visual>
  <collision>
    <origin xyz="-0.05713 -0.002855 -0.28806" rpy="0 0 0"/>
    <geometry>
      <mesh filename="package://ruxonros2_description/meshes/Y_1.stl" scale="0.001 0.001 0.001"/>
    </geometry>
  </collision>
</link>

<link name="Z_1">
  <inertial>
    <origin xyz="-0.04236968206222333 -0.042146819203015065 0.012476523607853784" rpy="0 0 0"/>
    <mass value="3.84628600467331"/>
    <inertia ixx="0.013533" iyy="0.007192" izz="0.012698" ixy="-2.7e-05" iyz="0.001679" ixz="-3.7e-05"/>
  </inertial>
  <visual>
    <origin xyz="-0.04339 -0.003782 -0.548929" rpy="0 0 0"/>
    <geometry>
      <mesh filename="package://ruxonros2_description/meshes/Z_1.stl" scale="0.001 0.001 0.001"/>
    </geometry>
    <material name="silver"/>
  </visual>
  <collision>
    <origin xyz="-0.04339 -0.003782 -0.548929" rpy="0 0 0"/>
    <geometry>
      <mesh filename="package://ruxonros2_description/meshes/Z_1.stl" scale="0.001 0.001 0.001"/>
    </geometry>
  </collision>
</link>

<link name="U_1">
  <inertial>
    <origin xyz="-8.24850289016083e-05 -0.050793003188884814 -0.0008968570947446297" rpy="0 0 0"/>
    <mass value="4.3577353651585975"/>
    <inertia ixx="0.016932" iyy="0.010224" izz="0.021927" ixy="1.2e-05" iyz="-0.000146" ixz="-6e-06"/>
  </inertial>
  <visual>
    <origin xyz="0.000819 0.119908 -0.570126" rpy="0 0 0"/>
    <geometry>
      <mesh filename="package://ruxonros2_description/meshes/U_1.stl" scale="0.001 0.001 0.001"/>
    </geometry>
    <material name="silver"/>
  </visual>
  <collision>
    <origin xyz="0.000819 0.119908 -0.570126" rpy="0 0 0"/>
    <geometry>
      <mesh filename="package://ruxonros2_description/meshes/U_1.stl" scale="0.001 0.001 0.001"/>
    </geometry>
  </collision>
</link>

<link name="V_1">
  <inertial>
    <origin xyz="0.03946749209280865 -0.016117009142551486 9.450002695476911e-05" rpy="0 0 0"/>
    <mass value="0.9512670697964065"/>
    <inertia ixx="0.001684" iyy="0.000817" izz="0.001479" ixy="-1e-06" iyz="-3e-06" ixz="0.0"/>
  </inertial>
  <visual>
    <origin xyz="0.04021 0.254971 -0.568148" rpy="0 0 0"/>
    <geometry>
      <mesh filename="package://ruxonros2_description/meshes/V_1.stl" scale="0.001 0.001 0.001"/>
    </geometry>
    <material name="silver"/>
  </visual>
  <collision>
    <origin xyz="0.04021 0.254971 -0.568148" rpy="0 0 0"/>
    <geometry>
      <mesh filename="package://ruxonros2_description/meshes/V_1.stl" scale="0.001 0.001 0.001"/>
    </geometry>
  </collision>
</link>

<link name="W_1">
  <inertial>
    <origin xyz="2.497777789842474e-07 -0.005485656829279373 -2.9308332064048592e-05" rpy="0 0 0"/>
    <mass value="0.19077878768476822"/>
    <inertia ixx="0.000159" iyy="0.000307" izz="0.000159" ixy="-0.0" iyz="0.0" ixz="-0.0"/>
  </inertial>
  <visual>
    <origin xyz="0.00071 0.313516 -0.568205" rpy="0 0 0"/>
    <geometry>
      <mesh filename="package://ruxonros2_description/meshes/W_1.stl" scale="0.001 0.001 0.001"/>
    </geometry>
    <material name="silver"/>
  </visual>
  <collision>
    <origin xyz="0.00071 0.313516 -0.568205" rpy="0 0 0"/>
    <geometry>
      <mesh filename="package://ruxonros2_description/meshes/W_1.stl" scale="0.001 0.001 0.001"/>
    </geometry>
  </collision>
</link>

<joint name="Rev28" type="revolute">
  <origin xyz="0.0 0.023029 0.111" rpy="0 0 0"/>
  <parent link="base_link"/>
  <child link="X_1"/>
  <axis xyz="-0.0 0.0 1.0"/>
  <limit upper="3.141593" lower="-3.141593" effort="100" velocity="100"/>
</joint>

<joint name="Rev29" type="revolute">
  <origin xyz="0.05713 -0.020174 0.17706" rpy="0 0 0"/>
  <parent link="X_1"/>
  <child link="Y_1"/>
  <axis xyz="1.0 -0.0 0.0"/>
  <limit upper="2.356194" lower="-1.047198" effort="100" velocity="100"/>
</joint>

<joint name="Rev30" type="revolute">
  <origin xyz="-0.01374 0.000927 0.260869" rpy="0 0 0"/>
  <parent link="Y_1"/>
  <child link="Z_1"/>
  <axis xyz="1.0 -0.0 0.0"/>
  <limit upper="0.872665" lower="-2.094395" effort="100" velocity="100"/>
</joint>

<joint name="Rev31" type="revolute">
  <origin xyz="-0.044209 -0.12369 0.021197" rpy="0 0 0"/>
  <parent link="Z_1"/>
  <child link="U_1"/>
  <axis xyz="-0.0 1.0 0.0"/>
  <limit upper="0.0" lower="-6.283185" effort="100" velocity="100"/>
</joint>

<joint name="Rev32" type="revolute">
  <origin xyz="-0.039391 -0.135063 -0.001978" rpy="0 0 0"/>
  <parent link="U_1"/>
  <child link="V_1"/>
  <axis xyz="-1.0 -0.0 -0.0"/>
  <limit upper="1.745329" lower="-1.745329" effort="100" velocity="100"/>
</joint>

<joint name="Rev33" type="revolute">
  <origin xyz="0.0395 -0.058545 5.7e-05" rpy="0 0 0"/>
  <parent link="V_1"/>
  <child link="W_1"/>
  <axis xyz="0.0 -1.0 -0.0"/>
  <limit upper="0.0" lower="-6.283185" effort="100" velocity="100"/>
</joint>

</robot>
